{
 "cells": [
  {
   "cell_type": "code",
   "execution_count": 11,
   "id": "ba9b75f9",
   "metadata": {},
   "outputs": [
    {
     "name": "stderr",
     "output_type": "stream",
     "text": [
      "/home/ec2-user/anaconda3/envs/python3/lib/python3.6/site-packages/boto3/compat.py:88: PythonDeprecationWarning: Boto3 will no longer support Python 3.6 starting May 30, 2022. To continue receiving service updates, bug fixes, and security updates please upgrade to Python 3.7 or later. More information can be found here: https://aws.amazon.com/blogs/developer/python-support-policy-updates-for-aws-sdks-and-tools/\n",
      "  warnings.warn(warning, PythonDeprecationWarning)\n"
     ]
    }
   ],
   "source": [
    "import boto3\n",
    "client = boto3.client('sagemaker')"
   ]
  },
  {
   "cell_type": "code",
   "execution_count": 12,
   "id": "0175e519",
   "metadata": {},
   "outputs": [],
   "source": [
    "package_group = \"ChurnPackageGroup\"\n",
    "model_packages = client.list_model_packages(ModelPackageGroupName = package_group)"
   ]
  },
  {
   "cell_type": "code",
   "execution_count": 14,
   "id": "a38e6c67",
   "metadata": {},
   "outputs": [
    {
     "name": "stdout",
     "output_type": "stream",
     "text": [
      "{'ModelPackageGroupName': 'ChurnPackageGroup', 'ModelPackageVersion': 2, 'ModelPackageArn': 'arn:aws:sagemaker:us-east-1:852619674999:model-package/churnpackagegroup/2', 'CreationTime': datetime.datetime(2022, 5, 22, 11, 3, 54, 986000, tzinfo=tzlocal()), 'ModelPackageStatus': 'Completed', 'ModelApprovalStatus': 'Approved'}\n",
      "arn:aws:sagemaker:us-east-1:852619674999:model-package/churnpackagegroup/2\n"
     ]
    }
   ],
   "source": [
    "latest_package = model_packages[\"ModelPackageSummaryList\"][0]\n",
    "latest_package_arn = latest_package[\"ModelPackageArn\"]\n",
    "\n",
    "print(latest_package)\n",
    "print(latest_package_arn)"
   ]
  },
  {
   "cell_type": "code",
   "execution_count": 15,
   "id": "72df139f",
   "metadata": {},
   "outputs": [],
   "source": [
    "latest_package_details = client.describe_model_package(ModelPackageName=latest_package_arn)"
   ]
  },
  {
   "cell_type": "code",
   "execution_count": null,
   "id": "2475f2e1",
   "metadata": {},
   "outputs": [],
   "source": [
    "latest_package_details"
   ]
  },
  {
   "cell_type": "code",
   "execution_count": 17,
   "id": "aa0369d7",
   "metadata": {},
   "outputs": [],
   "source": [
    "from sagemaker.model import Model"
   ]
  },
  {
   "cell_type": "code",
   "execution_count": 27,
   "id": "261d3d4d",
   "metadata": {},
   "outputs": [],
   "source": [
    "inference_model = Model(image_uri = latest_package_details['InferenceSpecification']['Containers'][0]['Image'], \n",
    "                        entry_point='SageMaker_Pipeline_Component_Codes/inference.py', \n",
    "                        model_data = latest_package_details['InferenceSpecification']['Containers'][0][\"ModelDataUrl\"], \n",
    "                        role = role\n",
    "                       )"
   ]
  },
  {
   "cell_type": "code",
   "execution_count": 28,
   "id": "bf687fd6",
   "metadata": {},
   "outputs": [],
   "source": [
    "inference_transformer = inference_model.transformer(instance_count = 1, \n",
    "                                                    instance_type = \"ml.m4.xlarge\", \n",
    "                                                    output_path = \"s3://demo-bucket-test-mlop/Eval/\"\n",
    "                                                   )"
   ]
  },
  {
   "cell_type": "code",
   "execution_count": 29,
   "id": "7d90308b",
   "metadata": {},
   "outputs": [
    {
     "name": "stdout",
     "output_type": "stream",
     "text": [
      "...................................\u001b[34m2022-05-22 12:48:43,402 INFO - sagemaker-containers - No GPUs detected (normal if no gpus installed)\u001b[0m\n",
      "\u001b[34m2022-05-22 12:48:43,405 INFO - sagemaker-containers - No GPUs detected (normal if no gpus installed)\u001b[0m\n",
      "\u001b[34m2022-05-22 12:48:43,405 INFO - sagemaker-containers - nginx config: \u001b[0m\n",
      "\u001b[34mworker_processes auto;\u001b[0m\n",
      "\u001b[34mdaemon off;\u001b[0m\n",
      "\u001b[34mpid /tmp/nginx.pid;\u001b[0m\n",
      "\u001b[34merror_log  /dev/stderr;\u001b[0m\n",
      "\u001b[34mworker_rlimit_nofile 4096;\u001b[0m\n",
      "\u001b[34mevents {\n",
      "  worker_connections 2048;\u001b[0m\n",
      "\u001b[34m}\u001b[0m\n",
      "\u001b[34mhttp {\n",
      "  include /etc/nginx/mime.types;\n",
      "  default_type application/octet-stream;\n",
      "  access_log /dev/stdout combined;\n",
      "  upstream gunicorn {\n",
      "    server unix:/tmp/gunicorn.sock;\n",
      "  }\n",
      "  server {\n",
      "    listen 8080 deferred;\n",
      "    client_max_body_size 0;\n",
      "    keepalive_timeout 3;\n",
      "    location ~ ^/(ping|invocations|execution-parameters) {\n",
      "      proxy_set_header X-Forwarded-For $proxy_add_x_forwarded_for;\n",
      "      proxy_set_header Host $http_host;\n",
      "      proxy_redirect off;\n",
      "      proxy_read_timeout 60s;\n",
      "      proxy_pass http://gunicorn;\n",
      "    }\n",
      "    location / {\n",
      "      return 404 \"{}\";\n",
      "    }\n",
      "  }\u001b[0m\n",
      "\u001b[34m}\u001b[0m\n",
      "\u001b[34m2022-05-22 12:48:43,707 INFO - sagemaker-containers - Module inference does not provide a setup.py. \u001b[0m\n",
      "\u001b[34mGenerating setup.py\u001b[0m\n",
      "\u001b[34m2022-05-22 12:48:43,707 INFO - sagemaker-containers - Generating setup.cfg\u001b[0m\n",
      "\u001b[34m2022-05-22 12:48:43,707 INFO - sagemaker-containers - Generating MANIFEST.in\u001b[0m\n",
      "\u001b[34m2022-05-22 12:48:43,708 INFO - sagemaker-containers - Installing module with the following command:\u001b[0m\n",
      "\u001b[34m/miniconda3/bin/python3 -m pip install . \u001b[0m\n",
      "\u001b[34mProcessing /opt/ml/code\n",
      "  Preparing metadata (setup.py): started\n",
      "  Preparing metadata (setup.py): finished with status 'done'\u001b[0m\n",
      "\u001b[34mBuilding wheels for collected packages: inference\n",
      "  Building wheel for inference (setup.py): started\n",
      "  Building wheel for inference (setup.py): finished with status 'done'\n",
      "  Created wheel for inference: filename=inference-1.0.0-py2.py3-none-any.whl size=5052 sha256=200180618913f314da50a57c40472b0472f16a0dc10c33685ad2015b8b7bf3dd\n",
      "  Stored in directory: /home/model-server/tmp/pip-ephem-wheel-cache-3_2syo62/wheels/3e/0f/51/2f1df833dd0412c1bc2f5ee56baac195b5be563353d111dca6\u001b[0m\n",
      "\u001b[34mSuccessfully built inference\u001b[0m\n",
      "\u001b[34mInstalling collected packages: inference\u001b[0m\n",
      "\u001b[34mSuccessfully installed inference-1.0.0\u001b[0m\n",
      "\u001b[34mWARNING: Running pip as the 'root' user can result in broken permissions and conflicting behaviour with the system package manager. It is recommended to use a virtual environment instead: https://pip.pypa.io/warnings/venv\u001b[0m\n",
      "\u001b[34mWARNING: You are using pip version 22.0.4; however, version 22.1.1 is available.\u001b[0m\n",
      "\u001b[34mYou should consider upgrading via the '/miniconda3/bin/python3 -m pip install --upgrade pip' command.\u001b[0m\n",
      "\u001b[34m[2022-05-22 12:48:46 +0000] [34] [INFO] Starting gunicorn 20.0.4\u001b[0m\n",
      "\u001b[34m[2022-05-22 12:48:46 +0000] [34] [INFO] Listening at: unix:/tmp/gunicorn.sock (34)\u001b[0m\n",
      "\u001b[34m[2022-05-22 12:48:46 +0000] [34] [INFO] Using worker: gevent\u001b[0m\n",
      "\u001b[34m[2022-05-22 12:48:46 +0000] [37] [INFO] Booting worker with pid: 37\u001b[0m\n",
      "\u001b[34m[2022-05-22 12:48:46 +0000] [38] [INFO] Booting worker with pid: 38\u001b[0m\n",
      "\u001b[34m[2022-05-22 12:48:46 +0000] [39] [INFO] Booting worker with pid: 39\u001b[0m\n",
      "\u001b[34m[2022-05-22 12:48:46 +0000] [40] [INFO] Booting worker with pid: 40\u001b[0m\n",
      "\u001b[34m2022-05-22 12:48:49,933 INFO - sagemaker-containers - No GPUs detected (normal if no gpus installed)\u001b[0m\n",
      "\u001b[34m2022-05-22 12:48:50,195 INFO - root - Inference started.\u001b[0m\n",
      "\u001b[34mInference started.\u001b[0m\n",
      "\u001b[34mFiles are\u001b[0m\n",
      "\u001b[34m['model.joblib']\u001b[0m\n",
      "\u001b[34m169.254.255.130 - - [22/May/2022:12:48:50 +0000] \"GET /ping HTTP/1.1\" 200 0 \"-\" \"Go-http-client/1.1\"\u001b[0m\n",
      "\u001b[34m169.254.255.130 - - [22/May/2022:12:48:50 +0000] \"GET /execution-parameters HTTP/1.1\" 404 232 \"-\" \"Go-http-client/1.1\"\u001b[0m\n",
      "\u001b[34m2022-05-22 12:48:50,626 INFO - sagemaker-containers - No GPUs detected (normal if no gpus installed)\u001b[0m\n",
      "\u001b[34m2022-05-22 12:48:50,866 INFO - root - Inference started.\u001b[0m\n",
      "\u001b[34mInference started.\u001b[0m\n",
      "\u001b[34mFiles are\u001b[0m\n",
      "\u001b[34m['model.joblib']\u001b[0m\n",
      "\u001b[34mInput data columns: Index(['State', 'Account length', 'Area code', 'International plan',\n",
      "       'Voice mail plan', 'Number vmail messages', 'Total day minutes',\n",
      "       'Total day calls', 'Total day charge', 'Total eve minutes',\n",
      "       'Total eve calls', 'Total eve charge', 'Total night minutes',\n",
      "       'Total night calls', 'Total night charge', 'Total intl minutes',\n",
      "       'Total intl calls', 'Total intl charge', 'Customer service calls'],\n",
      "      dtype='object')\u001b[0m\n",
      "\u001b[34m2022-05-22 12:48:51,234 ERROR - inference - Exception on /invocations [POST]\u001b[0m\n",
      "\u001b[34mTraceback (most recent call last):\n",
      "  File \"/miniconda3/lib/python3.7/site-packages/sagemaker_containers/_functions.py\", line 93, in wrapper\n",
      "    return fn(*args, **kwargs)\n",
      "  File \"/opt/ml/code/inference.py\", line 88, in predict_fn\n",
      "    features = model.predict(input_data)\n",
      "  File \"/miniconda3/lib/python3.7/site-packages/sklearn/tree/_classes.py\", line 427, in predict\n",
      "    X = self._validate_X_predict(X, check_input)\n",
      "  File \"/miniconda3/lib/python3.7/site-packages/sklearn/tree/_classes.py\", line 388, in _validate_X_predict\n",
      "    X = check_array(X, dtype=DTYPE, accept_sparse=\"csr\")\n",
      "  File \"/miniconda3/lib/python3.7/site-packages/sklearn/utils/validation.py\", line 72, in inner_f\n",
      "    return f(**kwargs)\n",
      "  File \"/miniconda3/lib/python3.7/site-packages/sklearn/utils/validation.py\", line 598, in check_array\n",
      "    array = np.asarray(array, order=order, dtype=dtype)\n",
      "  File \"/miniconda3/lib/python3.7/site-packages/pandas/core/generic.py\", line 1781, in __array__\n",
      "    return np.asarray(self._values, dtype=dtype)\u001b[0m\n",
      "\u001b[34mValueError: could not convert string to float: 'LA'\u001b[0m\n",
      "\u001b[34mDuring handling of the above exception, another exception occurred:\u001b[0m\n",
      "\u001b[34mTraceback (most recent call last):\n",
      "  File \"/miniconda3/lib/python3.7/site-packages/flask/app.py\", line 2446, in wsgi_app\n",
      "    response = self.full_dispatch_request()\n",
      "  File \"/miniconda3/lib/python3.7/site-packages/flask/app.py\", line 1951, in full_dispatch_request\n",
      "    rv = self.handle_user_exception(e)\n",
      "  File \"/miniconda3/lib/python3.7/site-packages/flask/app.py\", line 1820, in handle_user_exception\n",
      "    reraise(exc_type, exc_value, tb)\n",
      "  File \"/miniconda3/lib/python3.7/site-packages/flask/_compat.py\", line 39, in reraise\n",
      "    raise value\n",
      "  File \"/miniconda3/lib/python3.7/site-packages/flask/app.py\", line 1949, in full_dispatch_request\n",
      "    rv = self.dispatch_request()\n",
      "  File \"/miniconda3/lib/python3.7/site-packages/flask/app.py\", line 1935, in dispatch_request\n",
      "    return self.view_functions[rule.endpoint](**req.view_args)\n",
      "  File \"/miniconda3/lib/python3.7/site-packages/sagemaker_containers/_transformer.py\", line 200, in transform\n",
      "    self._model, request.content, request.content_type, request.accept\n",
      "  File \"/miniconda3/lib/python3.7/site-packages/sagemaker_containers/_transformer.py\", line 231, in _default_transform_fn\n",
      "    prediction = self._predict_fn(data, model)\n",
      "  File \"/miniconda3/lib/python3.7/site-packages/sagemaker_containers/_functions.py\", line 95, in wrapper\n",
      "    six.reraise(error_class, error_class(e), sys.exc_info()[2])\n",
      "  File \"/miniconda3/lib/python3.7/site-packages/six.py\", line 702, in reraise\n",
      "    raise value.with_traceback(tb)\n",
      "  File \"/miniconda3/lib/python3.7/site-packages/sagemaker_containers/_functions.py\", line 93, in wrapper\n",
      "    return fn(*args, **kwargs)\n",
      "  File \"/opt/ml/code/inference.py\", line 88, in predict_fn\n",
      "    features = model.predict(input_data)\n",
      "  File \"/miniconda3/lib/python3.7/site-packages/sklearn/tree/_classes.py\", line 427, in predict\n",
      "    X = self._validate_X_predict(X, check_input)\n",
      "  File \"/miniconda3/lib/python3.7/site-packages/sklearn/tree/_classes.py\", line 388, in _validate_X_predict\n",
      "    X = check_array(X, dtype=DTYPE, accept_sparse=\"csr\")\n",
      "  File \"/miniconda3/lib/python3.7/site-packages/sklearn/utils/validation.py\", line 72, in inner_f\n",
      "    return f(**kwargs)\n",
      "  File \"/miniconda3/lib/python3.7/site-packages/sklearn/utils/validation.py\", line 598, in check_array\n",
      "    array = np.asarray(array, order=order, dtype=dtype)\n",
      "  File \"/miniconda3/lib/python3.7/site-packages/pandas/core/generic.py\", line 1781, in __array__\n",
      "    return np.asarray(self._values, dtype=dtype)\u001b[0m\n",
      "\u001b[34msagemaker_containers._errors.ClientError: could not convert string to float: 'LA'\u001b[0m\n",
      "\u001b[34mException on /invocations [POST]\u001b[0m\n",
      "\u001b[34mTraceback (most recent call last):\n",
      "  File \"/miniconda3/lib/python3.7/site-packages/sagemaker_containers/_functions.py\", line 93, in wrapper\n",
      "    return fn(*args, **kwargs)\n",
      "  File \"/opt/ml/code/inference.py\", line 88, in predict_fn\n",
      "    features = model.predict(input_data)\n",
      "  File \"/miniconda3/lib/python3.7/site-packages/sklearn/tree/_classes.py\", line 427, in predict\n",
      "    X = self._validate_X_predict(X, check_input)\n",
      "  File \"/miniconda3/lib/python3.7/site-packages/sklearn/tree/_classes.py\", line 388, in _validate_X_predict\n",
      "    X = check_array(X, dtype=DTYPE, accept_sparse=\"csr\")\n",
      "  File \"/miniconda3/lib/python3.7/site-packages/sklearn/utils/validation.py\", line 72, in inner_f\n",
      "    return f(**kwargs)\n",
      "  File \"/miniconda3/lib/python3.7/site-packages/sklearn/utils/validation.py\", line 598, in check_array\n",
      "    array = np.asarray(array, order=order, dtype=dtype)\n",
      "  File \"/miniconda3/lib/python3.7/site-packages/pandas/core/generic.py\", line 1781, in __array__\n",
      "    return np.asarray(self._values, dtype=dtype)\u001b[0m\n",
      "\u001b[34mValueError: could not convert string to float: 'LA'\u001b[0m\n",
      "\u001b[34mDuring handling of the above exception, another exception occurred:\u001b[0m\n",
      "\u001b[34mTraceback (most recent call last):\n",
      "  File \"/miniconda3/lib/python3.7/site-packages/flask/app.py\", line 2446, in wsgi_app\n",
      "    response = self.full_dispatch_request()\n",
      "  File \"/miniconda3/lib/python3.7/site-packages/flask/app.py\", line 1951, in full_dispatch_request\n",
      "    rv = self.handle_user_exception(e)\n",
      "  File \"/miniconda3/lib/python3.7/site-packages/flask/app.py\", line 1820, in handle_user_exception\n",
      "    reraise(exc_type, exc_value, tb)\n",
      "  File \"/miniconda3/lib/python3.7/site-packages/flask/_compat.py\", line 39, in reraise\n",
      "    raise value\n",
      "  File \"/miniconda3/lib/python3.7/site-packages/flask/app.py\", line 1949, in full_dispatch_request\n",
      "    rv = self.dispatch_request()\n",
      "  File \"/miniconda3/lib/python3.7/site-packages/flask/app.py\", line 1935, in dispatch_request\n",
      "    return self.view_functions[rule.endpoint](**req.view_args)\n",
      "  File \"/miniconda3/lib/python3.7/site-packages/sagemaker_containers/_transformer.py\", line 200, in transform\n",
      "    self._model, request.content, request.content_type, request.accept\n",
      "  File \"/miniconda3/lib/python3.7/site-packages/sagemaker_containers/_transformer.py\", line 231, in _default_transform_fn\n",
      "    prediction = self._predict_fn(data, model)\n",
      "  File \"/miniconda3/lib/python3.7/site-packages/sagemaker_containers/_functions.py\", line 95, in wrapper\n",
      "    six.reraise(error_class, error_class(e), sys.exc_info()[2])\n",
      "  File \"/miniconda3/lib/python3.7/site-packages/six.py\", line 702, in reraise\n",
      "    raise value.with_traceback(tb)\n",
      "  File \"/miniconda3/lib/python3.7/site-packages/sagemaker_containers/_functions.py\", line 93, in wrapper\n",
      "    return fn(*args, **kwargs)\n",
      "  File \"/opt/ml/code/inference.py\", line 88, in predict_fn\n",
      "    features = model.predict(input_data)\n",
      "  File \"/miniconda3/lib/python3.7/site-packages/sklearn/tree/_classes.py\", line 427, in predict\n",
      "    X = self._validate_X_predict(X, check_input)\n",
      "  File \"/miniconda3/lib/python3.7/site-packages/sklearn/tree/_classes.py\", line 388, in _validate_X_predict\n",
      "    X = check_array(X, dtype=DTYPE, accept_sparse=\"csr\")\n",
      "  File \"/miniconda3/lib/python3.7/site-packages/sklearn/utils/validation.py\", line 72, in inner_f\n",
      "    return f(**kwargs)\n",
      "  File \"/miniconda3/lib/python3.7/site-packages/sklearn/utils/validation.py\", line 598, in check_array\n",
      "    array = np.asarray(array, order=order, dtype=dtype)\n",
      "  File \"/miniconda3/lib/python3.7/site-packages/pandas/core/generic.py\", line 1781, in __array__\n",
      "    return np.asarray(self._values, dtype=dtype)\u001b[0m\n",
      "\u001b[34msagemaker_containers._errors.ClientError: could not convert string to float: 'LA'\u001b[0m\n",
      "\u001b[34m169.254.255.130 - - [22/May/2022:12:48:51 +0000] \"POST /invocations HTTP/1.1\" 500 290 \"-\" \"Go-http-client/1.1\"\u001b[0m\n",
      "\u001b[34m2022-05-22 12:48:51,262 INFO - sagemaker-containers - No GPUs detected (normal if no gpus installed)\u001b[0m\n",
      "\u001b[34m2022-05-22 12:48:51,492 INFO - root - Inference started.\u001b[0m\n",
      "\u001b[34mFiles are\u001b[0m\n",
      "\u001b[34m['model.joblib']\u001b[0m\n",
      "\u001b[34mInference started.\u001b[0m\n",
      "\u001b[34mInput data columns: Index(['State', 'Account length', 'Area code', 'International plan',\n",
      "       'Voice mail plan', 'Number vmail messages', 'Total day minutes',\n",
      "       'Total day calls', 'Total day charge', 'Total eve minutes',\n",
      "       'Total eve calls', 'Total eve charge', 'Total night minutes',\n",
      "       'Total night calls', 'Total night charge', 'Total intl minutes',\n",
      "       'Total intl calls', 'Total intl charge', 'Customer service calls'],\n",
      "      dtype='object')\u001b[0m\n",
      "\u001b[34m2022-05-22 12:48:51,882 ERROR - inference - Exception on /invocations [POST]\u001b[0m\n",
      "\u001b[34mTraceback (most recent call last):\n",
      "  File \"/miniconda3/lib/python3.7/site-packages/sagemaker_containers/_functions.py\", line 93, in wrapper\n",
      "    return fn(*args, **kwargs)\n",
      "  File \"/opt/ml/code/inference.py\", line 88, in predict_fn\n",
      "    features = model.predict(input_data)\n",
      "  File \"/miniconda3/lib/python3.7/site-packages/sklearn/tree/_classes.py\", line 427, in predict\n",
      "    X = self._validate_X_predict(X, check_input)\n",
      "  File \"/miniconda3/lib/python3.7/site-packages/sklearn/tree/_classes.py\", line 388, in _validate_X_predict\n",
      "    X = check_array(X, dtype=DTYPE, accept_sparse=\"csr\")\n",
      "  File \"/miniconda3/lib/python3.7/site-packages/sklearn/utils/validation.py\", line 72, in inner_f\n",
      "    return f(**kwargs)\n",
      "  File \"/miniconda3/lib/python3.7/site-packages/sklearn/utils/validation.py\", line 598, in check_array\n",
      "    array = np.asarray(array, order=order, dtype=dtype)\n",
      "  File \"/miniconda3/lib/python3.7/site-packages/pandas/core/generic.py\", line 1781, in __array__\n",
      "    return np.asarray(self._values, dtype=dtype)\u001b[0m\n",
      "\u001b[34mValueError: could not convert string to float: 'LA'\u001b[0m\n",
      "\u001b[34mDuring handling of the above exception, another exception occurred:\u001b[0m\n",
      "\u001b[34mTraceback (most recent call last):\n",
      "  File \"/miniconda3/lib/python3.7/site-packages/flask/app.py\", line 2446, in wsgi_app\n",
      "    response = self.full_dispatch_request()\n",
      "  File \"/miniconda3/lib/python3.7/site-packages/flask/app.py\", line 1951, in full_dispatch_request\n",
      "    rv = self.handle_user_exception(e)\n",
      "  File \"/miniconda3/lib/python3.7/site-packages/flask/app.py\", line 1820, in handle_user_exception\n",
      "    reraise(exc_type, exc_value, tb)\n",
      "  File \"/miniconda3/lib/python3.7/site-packages/flask/_compat.py\", line 39, in reraise\n",
      "    raise value\n",
      "  File \"/miniconda3/lib/python3.7/site-packages/flask/app.py\", line 1949, in full_dispatch_request\n",
      "    rv = self.dispatch_request()\n",
      "  File \"/miniconda3/lib/python3.7/site-packages/flask/app.py\", line 1935, in dispatch_request\n",
      "    return self.view_functions[rule.endpoint](**req.view_args)\n",
      "  File \"/miniconda3/lib/python3.7/site-packages/sagemaker_containers/_transformer.py\", line 200, in transform\n",
      "    self._model, request.content, request.content_type, request.accept\n",
      "  File \"/miniconda3/lib/python3.7/site-packages/sagemaker_containers/_transformer.py\", line 231, in _default_transform_fn\n",
      "    prediction = self._predict_fn(data, model)\n",
      "  File \"/miniconda3/lib/python3.7/site-packages/sagemaker_containers/_functions.py\", line 95, in wrapper\n",
      "    six.reraise(error_class, error_class(e), sys.exc_info()[2])\n",
      "  File \"/miniconda3/lib/python3.7/site-packages/six.py\", line 702, in reraise\n",
      "    raise value.with_traceback(tb)\n",
      "  File \"/miniconda3/lib/python3.7/site-packages/sagemaker_containers/_functions.py\", line 93, in wrapper\n",
      "    return fn(*args, **kwargs)\n",
      "  File \"/opt/ml/code/inference.py\", line 88, in predict_fn\n",
      "    features = model.predict(input_data)\n",
      "  File \"/miniconda3/lib/python3.7/site-packages/sklearn/tree/_classes.py\", line 427, in predict\n",
      "    X = self._validate_X_predict(X, check_input)\n",
      "  File \"/miniconda3/lib/python3.7/site-packages/sklearn/tree/_classes.py\", line 388, in _validate_X_predict\n",
      "    X = check_array(X, dtype=DTYPE, accept_sparse=\"csr\")\n",
      "  File \"/miniconda3/lib/python3.7/site-packages/sklearn/utils/validation.py\", line 72, in inner_f\n",
      "    return f(**kwargs)\n",
      "  File \"/miniconda3/lib/python3.7/site-packages/sklearn/utils/validation.py\", line 598, in check_array\n",
      "    array = np.asarray(array, order=order, dtype=dtype)\n",
      "  File \"/miniconda3/lib/python3.7/site-packages/pandas/core/generic.py\", line 1781, in __array__\n",
      "    return np.asarray(self._values, dtype=dtype)\u001b[0m\n",
      "\u001b[34msagemaker_containers._errors.ClientError: could not convert string to float: 'LA'\u001b[0m\n",
      "\u001b[34mException on /invocations [POST]\u001b[0m\n",
      "\u001b[34mTraceback (most recent call last):\n",
      "  File \"/miniconda3/lib/python3.7/site-packages/sagemaker_containers/_functions.py\", line 93, in wrapper\n",
      "    return fn(*args, **kwargs)\n",
      "  File \"/opt/ml/code/inference.py\", line 88, in predict_fn\n",
      "    features = model.predict(input_data)\n",
      "  File \"/miniconda3/lib/python3.7/site-packages/sklearn/tree/_classes.py\", line 427, in predict\n",
      "    X = self._validate_X_predict(X, check_input)\n",
      "  File \"/miniconda3/lib/python3.7/site-packages/sklearn/tree/_classes.py\", line 388, in _validate_X_predict\n",
      "    X = check_array(X, dtype=DTYPE, accept_sparse=\"csr\")\n",
      "  File \"/miniconda3/lib/python3.7/site-packages/sklearn/utils/validation.py\", line 72, in inner_f\n",
      "    return f(**kwargs)\n",
      "  File \"/miniconda3/lib/python3.7/site-packages/sklearn/utils/validation.py\", line 598, in check_array\n",
      "    array = np.asarray(array, order=order, dtype=dtype)\n",
      "  File \"/miniconda3/lib/python3.7/site-packages/pandas/core/generic.py\", line 1781, in __array__\n",
      "    return np.asarray(self._values, dtype=dtype)\u001b[0m\n",
      "\u001b[34mValueError: could not convert string to float: 'LA'\u001b[0m\n",
      "\u001b[34mDuring handling of the above exception, another exception occurred:\u001b[0m\n",
      "\u001b[34mTraceback (most recent call last):\n",
      "  File \"/miniconda3/lib/python3.7/site-packages/flask/app.py\", line 2446, in wsgi_app\n",
      "    response = self.full_dispatch_request()\n",
      "  File \"/miniconda3/lib/python3.7/site-packages/flask/app.py\", line 1951, in full_dispatch_request\n",
      "    rv = self.handle_user_exception(e)\n",
      "  File \"/miniconda3/lib/python3.7/site-packages/flask/app.py\", line 1820, in handle_user_exception\n",
      "    reraise(exc_type, exc_value, tb)\n",
      "  File \"/miniconda3/lib/python3.7/site-packages/flask/_compat.py\", line 39, in reraise\n",
      "    raise value\n",
      "  File \"/miniconda3/lib/python3.7/site-packages/flask/app.py\", line 1949, in full_dispatch_request\n",
      "    rv = self.dispatch_request()\n",
      "  File \"/miniconda3/lib/python3.7/site-packages/flask/app.py\", line 1935, in dispatch_request\n",
      "    return self.view_functions[rule.endpoint](**req.view_args)\n",
      "  File \"/miniconda3/lib/python3.7/site-packages/sagemaker_containers/_transformer.py\", line 200, in transform\n",
      "    self._model, request.content, request.content_type, request.accept\n",
      "  File \"/miniconda3/lib/python3.7/site-packages/sagemaker_containers/_transformer.py\", line 231, in _default_transform_fn\n",
      "    prediction = self._predict_fn(data, model)\n",
      "  File \"/miniconda3/lib/python3.7/site-packages/sagemaker_containers/_functions.py\", line 95, in wrapper\n",
      "    six.reraise(error_class, error_class(e), sys.exc_info()[2])\n",
      "  File \"/miniconda3/lib/python3.7/site-packages/six.py\", line 702, in reraise\n",
      "    raise value.with_traceback(tb)\n",
      "  File \"/miniconda3/lib/python3.7/site-packages/sagemaker_containers/_functions.py\", line 93, in wrapper\n",
      "    return fn(*args, **kwargs)\n",
      "  File \"/opt/ml/code/inference.py\", line 88, in predict_fn\n",
      "    features = model.predict(input_data)\n",
      "  File \"/miniconda3/lib/python3.7/site-packages/sklearn/tree/_classes.py\", line 427, in predict\n",
      "    X = self._validate_X_predict(X, check_input)\n",
      "  File \"/miniconda3/lib/python3.7/site-packages/sklearn/tree/_classes.py\", line 388, in _validate_X_predict\n",
      "    X = check_array(X, dtype=DTYPE, accept_sparse=\"csr\")\n",
      "  File \"/miniconda3/lib/python3.7/site-packages/sklearn/utils/validation.py\", line 72, in inner_f\n",
      "    return f(**kwargs)\n",
      "  File \"/miniconda3/lib/python3.7/site-packages/sklearn/utils/validation.py\", line 598, in check_array\n",
      "    array = np.asarray(array, order=order, dtype=dtype)\n",
      "  File \"/miniconda3/lib/python3.7/site-packages/pandas/core/generic.py\", line 1781, in __array__\n",
      "    return np.asarray(self._values, dtype=dtype)\u001b[0m\n",
      "\u001b[34msagemaker_containers._errors.ClientError: could not convert string to float: 'LA'\u001b[0m\n",
      "\u001b[34m169.254.255.130 - - [22/May/2022:12:48:51 +0000] \"POST /invocations HTTP/1.1\" 500 290 \"-\" \"Go-http-client/1.1\"\u001b[0m\n",
      "\u001b[34mInput data columns: Index(['State', 'Account length', 'Area code', 'International plan',\n",
      "       'Voice mail plan', 'Number vmail messages', 'Total day minutes',\n",
      "       'Total day calls', 'Total day charge', 'Total eve minutes',\n",
      "       'Total eve calls', 'Total eve charge', 'Total night minutes',\n",
      "       'Total night calls', 'Total night charge', 'Total intl minutes',\n",
      "       'Total intl calls', 'Total intl charge', 'Customer service calls'],\n",
      "      dtype='object')\u001b[0m\n",
      "\u001b[34m2022-05-22 12:48:51,907 ERROR - inference - Exception on /invocations [POST]\u001b[0m\n",
      "\u001b[34mTraceback (most recent call last):\n",
      "  File \"/miniconda3/lib/python3.7/site-packages/sagemaker_containers/_functions.py\", line 93, in wrapper\n",
      "    return fn(*args, **kwargs)\n",
      "  File \"/opt/ml/code/inference.py\", line 88, in predict_fn\n",
      "    features = model.predict(input_data)\n",
      "  File \"/miniconda3/lib/python3.7/site-packages/sklearn/tree/_classes.py\", line 427, in predict\n",
      "    X = self._validate_X_predict(X, check_input)\n",
      "  File \"/miniconda3/lib/python3.7/site-packages/sklearn/tree/_classes.py\", line 388, in _validate_X_predict\n",
      "    X = check_array(X, dtype=DTYPE, accept_sparse=\"csr\")\n",
      "  File \"/miniconda3/lib/python3.7/site-packages/sklearn/utils/validation.py\", line 72, in inner_f\n",
      "    return f(**kwargs)\n",
      "  File \"/miniconda3/lib/python3.7/site-packages/sklearn/utils/validation.py\", line 598, in check_array\n",
      "    array = np.asarray(array, order=order, dtype=dtype)\n",
      "  File \"/miniconda3/lib/python3.7/site-packages/pandas/core/generic.py\", line 1781, in __array__\n",
      "    return np.asarray(self._values, dtype=dtype)\u001b[0m\n",
      "\u001b[34mValueError: could not convert string to float: 'LA'\u001b[0m\n",
      "\u001b[34mDuring handling of the above exception, another exception occurred:\u001b[0m\n",
      "\u001b[34mTraceback (most recent call last):\n",
      "  File \"/miniconda3/lib/python3.7/site-packages/flask/app.py\", line 2446, in wsgi_app\n",
      "    response = self.full_dispatch_request()\n",
      "  File \"/miniconda3/lib/python3.7/site-packages/flask/app.py\", line 1951, in full_dispatch_request\n",
      "    rv = self.handle_user_exception(e)\n",
      "  File \"/miniconda3/lib/python3.7/site-packages/flask/app.py\", line 1820, in handle_user_exception\n",
      "    reraise(exc_type, exc_value, tb)\n",
      "  File \"/miniconda3/lib/python3.7/site-packages/flask/_compat.py\", line 39, in reraise\n",
      "    raise value\n",
      "  File \"/miniconda3/lib/python3.7/site-packages/flask/app.py\", line 1949, in full_dispatch_request\n",
      "    rv = self.dispatch_request()\n",
      "  File \"/miniconda3/lib/python3.7/site-packages/flask/app.py\", line 1935, in dispatch_request\n",
      "    return self.view_functions[rule.endpoint](**req.view_args)\n",
      "  File \"/miniconda3/lib/python3.7/site-packages/sagemaker_containers/_transformer.py\", line 200, in transform\n",
      "    self._model, request.content, request.content_type, request.accept\n",
      "  File \"/miniconda3/lib/python3.7/site-packages/sagemaker_containers/_transformer.py\", line 231, in _default_transform_fn\n",
      "    prediction = self._predict_fn(data, model)\n",
      "  File \"/miniconda3/lib/python3.7/site-packages/sagemaker_containers/_functions.py\", line 95, in wrapper\n",
      "    six.reraise(error_class, error_class(e), sys.exc_info()[2])\n",
      "  File \"/miniconda3/lib/python3.7/site-packages/six.py\", line 702, in reraise\n",
      "    raise value.with_traceback(tb)\n",
      "  File \"/miniconda3/lib/python3.7/site-packages/sagemaker_containers/_functions.py\", line 93, in wrapper\n",
      "    return fn(*args, **kwargs)\n",
      "  File \"/opt/ml/code/inference.py\", line 88, in predict_fn\n",
      "    features = model.predict(input_data)\n",
      "  File \"/miniconda3/lib/python3.7/site-packages/sklearn/tree/_classes.py\", line 427, in predict\n",
      "    X = self._validate_X_predict(X, check_input)\n",
      "  File \"/miniconda3/lib/python3.7/site-packages/sklearn/tree/_classes.py\", line 388, in _validate_X_predict\n",
      "    X = check_array(X, dtype=DTYPE, accept_sparse=\"csr\")\n",
      "  File \"/miniconda3/lib/python3.7/site-packages/sklearn/utils/validation.py\", line 72, in inner_f\n",
      "    return f(**kwargs)\u001b[0m\n",
      "\u001b[34m169.254.255.130 - - [22/May/2022:12:48:51 +0000] \"POST /invocations HTTP/1.1\" 500 290 \"-\" \"Go-http-client/1.1\"\n",
      "  File \"/miniconda3/lib/python3.7/site-packages/sklearn/utils/validation.py\", line 598, in check_array\n",
      "    array = np.asarray(array, order=order, dtype=dtype)\n",
      "  File \"/miniconda3/lib/python3.7/site-packages/pandas/core/generic.py\", line 1781, in __array__\n",
      "    return np.asarray(self._values, dtype=dtype)\u001b[0m\n",
      "\u001b[34msagemaker_containers._errors.ClientError: could not convert string to float: 'LA'\u001b[0m\n",
      "\u001b[34mException on /invocations [POST]\u001b[0m\n",
      "\u001b[34mTraceback (most recent call last):\n",
      "  File \"/miniconda3/lib/python3.7/site-packages/sagemaker_containers/_functions.py\", line 93, in wrapper\n",
      "    return fn(*args, **kwargs)\n",
      "  File \"/opt/ml/code/inference.py\", line 88, in predict_fn\n",
      "    features = model.predict(input_data)\n",
      "  File \"/miniconda3/lib/python3.7/site-packages/sklearn/tree/_classes.py\", line 427, in predict\n",
      "    X = self._validate_X_predict(X, check_input)\n",
      "  File \"/miniconda3/lib/python3.7/site-packages/sklearn/tree/_classes.py\", line 388, in _validate_X_predict\n",
      "    X = check_array(X, dtype=DTYPE, accept_sparse=\"csr\")\n",
      "  File \"/miniconda3/lib/python3.7/site-packages/sklearn/utils/validation.py\", line 72, in inner_f\n",
      "    return f(**kwargs)\n",
      "  File \"/miniconda3/lib/python3.7/site-packages/sklearn/utils/validation.py\", line 598, in check_array\n",
      "    array = np.asarray(array, order=order, dtype=dtype)\n",
      "  File \"/miniconda3/lib/python3.7/site-packages/pandas/core/generic.py\", line 1781, in __array__\n",
      "    return np.asarray(self._values, dtype=dtype)\u001b[0m\n",
      "\u001b[34mValueError: could not convert string to float: 'LA'\u001b[0m\n",
      "\u001b[34mDuring handling of the above exception, another exception occurred:\u001b[0m\n",
      "\u001b[34mTraceback (most recent call last):\n",
      "  File \"/miniconda3/lib/python3.7/site-packages/flask/app.py\", line 2446, in wsgi_app\n",
      "    response = self.full_dispatch_request()\n",
      "  File \"/miniconda3/lib/python3.7/site-packages/flask/app.py\", line 1951, in full_dispatch_request\n",
      "    rv = self.handle_user_exception(e)\n",
      "  File \"/miniconda3/lib/python3.7/site-packages/flask/app.py\", line 1820, in handle_user_exception\n",
      "    reraise(exc_type, exc_value, tb)\n",
      "  File \"/miniconda3/lib/python3.7/site-packages/flask/_compat.py\", line 39, in reraise\n",
      "    raise value\n",
      "  File \"/miniconda3/lib/python3.7/site-packages/flask/app.py\", line 1949, in full_dispatch_request\n",
      "    rv = self.dispatch_request()\n",
      "  File \"/miniconda3/lib/python3.7/site-packages/flask/app.py\", line 1935, in dispatch_request\n",
      "    return self.view_functions[rule.endpoint](**req.view_args)\n",
      "  File \"/miniconda3/lib/python3.7/site-packages/sagemaker_containers/_transformer.py\", line 200, in transform\n",
      "    self._model, request.content, request.content_type, request.accept\n",
      "  File \"/miniconda3/lib/python3.7/site-packages/sagemaker_containers/_transformer.py\", line 231, in _default_transform_fn\n",
      "    prediction = self._predict_fn(data, model)\n",
      "  File \"/miniconda3/lib/python3.7/site-packages/sagemaker_containers/_functions.py\", line 95, in wrapper\n",
      "    six.reraise(error_class, error_class(e), sys.exc_info()[2])\n",
      "  File \"/miniconda3/lib/python3.7/site-packages/six.py\", line 702, in reraise\n",
      "    raise value.with_traceback(tb)\n",
      "  File \"/miniconda3/lib/python3.7/site-packages/sagemaker_containers/_functions.py\", line 93, in wrapper\n",
      "    return fn(*args, **kwargs)\n",
      "  File \"/opt/ml/code/inference.py\", line 88, in predict_fn\n",
      "    features = model.predict(input_data)\n",
      "  File \"/miniconda3/lib/python3.7/site-packages/sklearn/tree/_classes.py\", line 427, in predict\n",
      "    X = self._validate_X_predict(X, check_input)\n",
      "  File \"/miniconda3/lib/python3.7/site-packages/sklearn/tree/_classes.py\", line 388, in _validate_X_predict\n",
      "    X = check_array(X, dtype=DTYPE, accept_sparse=\"csr\")\n",
      "  File \"/miniconda3/lib/python3.7/site-packages/sklearn/utils/validation.py\", line 72, in inner_f\n",
      "    return f(**kwargs)\n",
      "  File \"/miniconda3/lib/python3.7/site-packages/sklearn/utils/validation.py\", line 598, in check_array\n",
      "    array = np.asarray(array, order=order, dtype=dtype)\n",
      "  File \"/miniconda3/lib/python3.7/site-packages/pandas/core/generic.py\", line 1781, in __array__\n",
      "    return np.asarray(self._values, dtype=dtype)\u001b[0m\n",
      "\u001b[34msagemaker_containers._errors.ClientError: could not convert string to float: 'LA'\u001b[0m\n",
      "\u001b[34mInput data columns: Index(['State', 'Account length', 'Area code', 'International plan',\n",
      "       'Voice mail plan', 'Number vmail messages', 'Total day minutes',\n",
      "       'Total day calls', 'Total day charge', 'Total eve minutes',\n",
      "       'Total eve calls', 'Total eve charge', 'Total night minutes',\n",
      "       'Total night calls', 'Total night charge', 'Total intl minutes',\n",
      "       'Total intl calls', 'Total intl charge', 'Customer service calls'],\n",
      "      dtype='object')\u001b[0m\n",
      "\u001b[34m2022-05-22 12:48:51,927 ERROR - inference - Exception on /invocations [POST]\u001b[0m\n",
      "\u001b[34mTraceback (most recent call last):\n",
      "  File \"/miniconda3/lib/python3.7/site-packages/sagemaker_containers/_functions.py\", line 93, in wrapper\n",
      "    return fn(*args, **kwargs)\n",
      "  File \"/opt/ml/code/inference.py\", line 88, in predict_fn\n",
      "    features = model.predict(input_data)\n",
      "  File \"/miniconda3/lib/python3.7/site-packages/sklearn/tree/_classes.py\", line 427, in predict\n",
      "    X = self._validate_X_predict(X, check_input)\n",
      "  File \"/miniconda3/lib/python3.7/site-packages/sklearn/tree/_classes.py\", line 388, in _validate_X_predict\n",
      "    X = check_array(X, dtype=DTYPE, accept_sparse=\"csr\")\n",
      "  File \"/miniconda3/lib/python3.7/site-packages/sklearn/utils/validation.py\", line 72, in inner_f\n",
      "    return f(**kwargs)\n",
      "  File \"/miniconda3/lib/python3.7/site-packages/sklearn/utils/validation.py\", line 598, in check_array\n",
      "    array = np.asarray(array, order=order, dtype=dtype)\n",
      "  File \"/miniconda3/lib/python3.7/site-packages/pandas/core/generic.py\", line 1781, in __array__\n",
      "    return np.asarray(self._values, dtype=dtype)\u001b[0m\n",
      "\u001b[34mValueError: could not convert string to float: 'LA'\u001b[0m\n",
      "\u001b[34mDuring handling of the above exception, another exception occurred:\u001b[0m\n",
      "\u001b[34mTraceback (most recent call last):\n",
      "  File \"/miniconda3/lib/python3.7/site-packages/flask/app.py\", line 2446, in wsgi_app\n",
      "    response = self.full_dispatch_request()\n",
      "  File \"/miniconda3/lib/python3.7/site-packages/flask/app.py\", line 1951, in full_dispatch_request\n",
      "    rv = self.handle_user_exception(e)\n",
      "  File \"/miniconda3/lib/python3.7/site-packages/flask/app.py\", line 1820, in handle_user_exception\n",
      "    reraise(exc_type, exc_value, tb)\n",
      "  File \"/miniconda3/lib/python3.7/site-packages/flask/_compat.py\", line 39, in reraise\n",
      "    raise value\n",
      "  File \"/miniconda3/lib/python3.7/site-packages/flask/app.py\", line 1949, in full_dispatch_request\u001b[0m\n",
      "\u001b[34m169.254.255.130 - - [22/May/2022:12:48:51 +0000] \"POST /invocations HTTP/1.1\" 500 290 \"-\" \"Go-http-client/1.1\"\n",
      "    rv = self.dispatch_request()\n",
      "  File \"/miniconda3/lib/python3.7/site-packages/flask/app.py\", line 1935, in dispatch_request\n",
      "    return self.view_functions[rule.endpoint](**req.view_args)\n",
      "  File \"/miniconda3/lib/python3.7/site-packages/sagemaker_containers/_transformer.py\", line 200, in transform\n",
      "    self._model, request.content, request.content_type, request.accept\n",
      "  File \"/miniconda3/lib/python3.7/site-packages/sagemaker_containers/_transformer.py\", line 231, in _default_transform_fn\n",
      "    prediction = self._predict_fn(data, model)\n",
      "  File \"/miniconda3/lib/python3.7/site-packages/sagemaker_containers/_functions.py\", line 95, in wrapper\n",
      "    six.reraise(error_class, error_class(e), sys.exc_info()[2])\n",
      "  File \"/miniconda3/lib/python3.7/site-packages/six.py\", line 702, in reraise\n",
      "    raise value.with_traceback(tb)\n",
      "  File \"/miniconda3/lib/python3.7/site-packages/sagemaker_containers/_functions.py\", line 93, in wrapper\n",
      "    return fn(*args, **kwargs)\n",
      "  File \"/opt/ml/code/inference.py\", line 88, in predict_fn\n",
      "    features = model.predict(input_data)\n",
      "  File \"/miniconda3/lib/python3.7/site-packages/sklearn/tree/_classes.py\", line 427, in predict\n",
      "    X = self._validate_X_predict(X, check_input)\n",
      "  File \"/miniconda3/lib/python3.7/site-packages/sklearn/tree/_classes.py\", line 388, in _validate_X_predict\n",
      "    X = check_array(X, dtype=DTYPE, accept_sparse=\"csr\")\n",
      "  File \"/miniconda3/lib/python3.7/site-packages/sklearn/utils/validation.py\", line 72, in inner_f\n",
      "    return f(**kwargs)\n",
      "  File \"/miniconda3/lib/python3.7/site-packages/sklearn/utils/validation.py\", line 598, in check_array\n",
      "    array = np.asarray(array, order=order, dtype=dtype)\n",
      "  File \"/miniconda3/lib/python3.7/site-packages/pandas/core/generic.py\", line 1781, in __array__\n",
      "    return np.asarray(self._values, dtype=dtype)\u001b[0m\n",
      "\u001b[34msagemaker_containers._errors.ClientError: could not convert string to float: 'LA'\u001b[0m\n",
      "\u001b[34mException on /invocations [POST]\u001b[0m\n",
      "\u001b[34mTraceback (most recent call last):\n",
      "  File \"/miniconda3/lib/python3.7/site-packages/sagemaker_containers/_functions.py\", line 93, in wrapper\n",
      "    return fn(*args, **kwargs)\n",
      "  File \"/opt/ml/code/inference.py\", line 88, in predict_fn\n",
      "    features = model.predict(input_data)\n",
      "  File \"/miniconda3/lib/python3.7/site-packages/sklearn/tree/_classes.py\", line 427, in predict\n",
      "    X = self._validate_X_predict(X, check_input)\n",
      "  File \"/miniconda3/lib/python3.7/site-packages/sklearn/tree/_classes.py\", line 388, in _validate_X_predict\n",
      "    X = check_array(X, dtype=DTYPE, accept_sparse=\"csr\")\n",
      "  File \"/miniconda3/lib/python3.7/site-packages/sklearn/utils/validation.py\", line 72, in inner_f\n",
      "    return f(**kwargs)\n",
      "  File \"/miniconda3/lib/python3.7/site-packages/sklearn/utils/validation.py\", line 598, in check_array\n",
      "    array = np.asarray(array, order=order, dtype=dtype)\n",
      "  File \"/miniconda3/lib/python3.7/site-packages/pandas/core/generic.py\", line 1781, in __array__\n",
      "    return np.asarray(self._values, dtype=dtype)\u001b[0m\n",
      "\u001b[34mValueError: could not convert string to float: 'LA'\u001b[0m\n",
      "\u001b[34mDuring handling of the above exception, another exception occurred:\u001b[0m\n",
      "\u001b[34mTraceback (most recent call last):\n",
      "  File \"/miniconda3/lib/python3.7/site-packages/flask/app.py\", line 2446, in wsgi_app\n",
      "    response = self.full_dispatch_request()\n",
      "  File \"/miniconda3/lib/python3.7/site-packages/flask/app.py\", line 1951, in full_dispatch_request\n",
      "    rv = self.handle_user_exception(e)\n",
      "  File \"/miniconda3/lib/python3.7/site-packages/flask/app.py\", line 1820, in handle_user_exception\n",
      "    reraise(exc_type, exc_value, tb)\n",
      "  File \"/miniconda3/lib/python3.7/site-packages/flask/_compat.py\", line 39, in reraise\n",
      "    raise value\n",
      "  File \"/miniconda3/lib/python3.7/site-packages/flask/app.py\", line 1949, in full_dispatch_request\n",
      "    rv = self.dispatch_request()\n",
      "  File \"/miniconda3/lib/python3.7/site-packages/flask/app.py\", line 1935, in dispatch_request\n",
      "    return self.view_functions[rule.endpoint](**req.view_args)\n",
      "  File \"/miniconda3/lib/python3.7/site-packages/sagemaker_containers/_transformer.py\", line 200, in transform\n",
      "    self._model, request.content, request.content_type, request.accept\n",
      "  File \"/miniconda3/lib/python3.7/site-packages/sagemaker_containers/_transformer.py\", line 231, in _default_transform_fn\n",
      "    prediction = self._predict_fn(data, model)\n",
      "  File \"/miniconda3/lib/python3.7/site-packages/sagemaker_containers/_functions.py\", line 95, in wrapper\n",
      "    six.reraise(error_class, error_class(e), sys.exc_info()[2])\n",
      "  File \"/miniconda3/lib/python3.7/site-packages/six.py\", line 702, in reraise\n",
      "    raise value.with_traceback(tb)\n",
      "  File \"/miniconda3/lib/python3.7/site-packages/sagemaker_containers/_functions.py\", line 93, in wrapper\n",
      "    return fn(*args, **kwargs)\n",
      "  File \"/opt/ml/code/inference.py\", line 88, in predict_fn\n",
      "    features = model.predict(input_data)\n",
      "  File \"/miniconda3/lib/python3.7/site-packages/sklearn/tree/_classes.py\", line 427, in predict\n",
      "    X = self._validate_X_predict(X, check_input)\n",
      "  File \"/miniconda3/lib/python3.7/site-packages/sklearn/tree/_classes.py\", line 388, in _validate_X_predict\n",
      "    X = check_array(X, dtype=DTYPE, accept_sparse=\"csr\")\n",
      "  File \"/miniconda3/lib/python3.7/site-packages/sklearn/utils/validation.py\", line 72, in inner_f\n",
      "    return f(**kwargs)\n",
      "  File \"/miniconda3/lib/python3.7/site-packages/sklearn/utils/validation.py\", line 598, in check_array\n",
      "    array = np.asarray(array, order=order, dtype=dtype)\n",
      "  File \"/miniconda3/lib/python3.7/site-packages/pandas/core/generic.py\", line 1781, in __array__\n",
      "    return np.asarray(self._values, dtype=dtype)\u001b[0m\n",
      "\u001b[34msagemaker_containers._errors.ClientError: could not convert string to float: 'LA'\u001b[0m\n",
      "\n",
      "\u001b[32m2022-05-22T12:48:50.579:[sagemaker logs]: MaxConcurrentTransforms=1, MaxPayloadInMB=6, BatchStrategy=MULTI_RECORD\u001b[0m\n",
      "\u001b[32m2022-05-22T12:48:51.936:[sagemaker logs]: demo-bucket-test-mlop/Churn_Demo/churn-bigml-20.csv: Bad HTTP status received from algorithm: 500\u001b[0m\n",
      "\u001b[32m2022-05-22T12:48:51.936:[sagemaker logs]: demo-bucket-test-mlop/Churn_Demo/churn-bigml-20.csv: \u001b[0m\n",
      "\u001b[32m2022-05-22T12:48:51.936:[sagemaker logs]: demo-bucket-test-mlop/Churn_Demo/churn-bigml-20.csv: Message:\u001b[0m\n",
      "\u001b[32m2022-05-22T12:48:51.936:[sagemaker logs]: demo-bucket-test-mlop/Churn_Demo/churn-bigml-20.csv: <!DOCTYPE HTML PUBLIC \"-//W3C//DTD HTML 3.2 Final//EN\">\u001b[0m\n",
      "\u001b[32m2022-05-22T12:48:51.936:[sagemaker logs]: demo-bucket-test-mlop/Churn_Demo/churn-bigml-20.csv: <title>500 Internal Server Error</title>\u001b[0m\n",
      "\u001b[32m2022-05-22T12:48:51.936:[sagemaker logs]: demo-bucket-test-mlop/Churn_Demo/churn-bigml-20.csv: <h1>Internal Server Error</h1>\u001b[0m\n",
      "\u001b[32m2022-05-22T12:48:51.936:[sagemaker logs]: demo-bucket-test-mlop/Churn_Demo/churn-bigml-20.csv: <p>The server encountered an internal error and was unable to complete your request. Either the server is overloaded or there is an error in the application.</p>\u001b[0m\n"
     ]
    },
    {
     "ename": "UnexpectedStatusException",
     "evalue": "Error for Transform job sagemaker-scikit-learn-2022-05-22-12-43-07-842: Failed. Reason: AlgorithmError: See job logs for more information",
     "output_type": "error",
     "traceback": [
      "\u001b[0;31m---------------------------------------------------------------------------\u001b[0m",
      "\u001b[0;31mUnexpectedStatusException\u001b[0m                 Traceback (most recent call last)",
      "\u001b[0;32m<ipython-input-29-2c9790edf454>\u001b[0m in \u001b[0;36m<module>\u001b[0;34m\u001b[0m\n\u001b[1;32m      1\u001b[0m inference_transformer.transform(data = \"s3://demo-bucket-test-mlop/Churn_Demo/churn-bigml-20.csv\", \n\u001b[0;32m----> 2\u001b[0;31m                                 content_type = \"text/csv\")\n\u001b[0m",
      "\u001b[0;32m~/anaconda3/envs/python3/lib/python3.6/site-packages/sagemaker/transformer.py\u001b[0m in \u001b[0;36mtransform\u001b[0;34m(self, data, data_type, content_type, compression_type, split_type, job_name, input_filter, output_filter, join_source, experiment_config, model_client_config, wait, logs)\u001b[0m\n\u001b[1;32m    223\u001b[0m \u001b[0;34m\u001b[0m\u001b[0m\n\u001b[1;32m    224\u001b[0m         \u001b[0;32mif\u001b[0m \u001b[0mwait\u001b[0m\u001b[0;34m:\u001b[0m\u001b[0;34m\u001b[0m\u001b[0;34m\u001b[0m\u001b[0m\n\u001b[0;32m--> 225\u001b[0;31m             \u001b[0mself\u001b[0m\u001b[0;34m.\u001b[0m\u001b[0mlatest_transform_job\u001b[0m\u001b[0;34m.\u001b[0m\u001b[0mwait\u001b[0m\u001b[0;34m(\u001b[0m\u001b[0mlogs\u001b[0m\u001b[0;34m=\u001b[0m\u001b[0mlogs\u001b[0m\u001b[0;34m)\u001b[0m\u001b[0;34m\u001b[0m\u001b[0;34m\u001b[0m\u001b[0m\n\u001b[0m\u001b[1;32m    226\u001b[0m \u001b[0;34m\u001b[0m\u001b[0m\n\u001b[1;32m    227\u001b[0m     \u001b[0;32mdef\u001b[0m \u001b[0mdelete_model\u001b[0m\u001b[0;34m(\u001b[0m\u001b[0mself\u001b[0m\u001b[0;34m)\u001b[0m\u001b[0;34m:\u001b[0m\u001b[0;34m\u001b[0m\u001b[0;34m\u001b[0m\u001b[0m\n",
      "\u001b[0;32m~/anaconda3/envs/python3/lib/python3.6/site-packages/sagemaker/transformer.py\u001b[0m in \u001b[0;36mwait\u001b[0;34m(self, logs)\u001b[0m\n\u001b[1;32m    419\u001b[0m     \u001b[0;32mdef\u001b[0m \u001b[0mwait\u001b[0m\u001b[0;34m(\u001b[0m\u001b[0mself\u001b[0m\u001b[0;34m,\u001b[0m \u001b[0mlogs\u001b[0m\u001b[0;34m=\u001b[0m\u001b[0;32mTrue\u001b[0m\u001b[0;34m)\u001b[0m\u001b[0;34m:\u001b[0m\u001b[0;34m\u001b[0m\u001b[0;34m\u001b[0m\u001b[0m\n\u001b[1;32m    420\u001b[0m         \u001b[0;32mif\u001b[0m \u001b[0mlogs\u001b[0m\u001b[0;34m:\u001b[0m\u001b[0;34m\u001b[0m\u001b[0;34m\u001b[0m\u001b[0m\n\u001b[0;32m--> 421\u001b[0;31m             \u001b[0mself\u001b[0m\u001b[0;34m.\u001b[0m\u001b[0msagemaker_session\u001b[0m\u001b[0;34m.\u001b[0m\u001b[0mlogs_for_transform_job\u001b[0m\u001b[0;34m(\u001b[0m\u001b[0mself\u001b[0m\u001b[0;34m.\u001b[0m\u001b[0mjob_name\u001b[0m\u001b[0;34m,\u001b[0m \u001b[0mwait\u001b[0m\u001b[0;34m=\u001b[0m\u001b[0;32mTrue\u001b[0m\u001b[0;34m)\u001b[0m\u001b[0;34m\u001b[0m\u001b[0;34m\u001b[0m\u001b[0m\n\u001b[0m\u001b[1;32m    422\u001b[0m         \u001b[0;32melse\u001b[0m\u001b[0;34m:\u001b[0m\u001b[0;34m\u001b[0m\u001b[0;34m\u001b[0m\u001b[0m\n\u001b[1;32m    423\u001b[0m             \u001b[0mself\u001b[0m\u001b[0;34m.\u001b[0m\u001b[0msagemaker_session\u001b[0m\u001b[0;34m.\u001b[0m\u001b[0mwait_for_transform_job\u001b[0m\u001b[0;34m(\u001b[0m\u001b[0mself\u001b[0m\u001b[0;34m.\u001b[0m\u001b[0mjob_name\u001b[0m\u001b[0;34m)\u001b[0m\u001b[0;34m\u001b[0m\u001b[0;34m\u001b[0m\u001b[0m\n",
      "\u001b[0;32m~/anaconda3/envs/python3/lib/python3.6/site-packages/sagemaker/session.py\u001b[0m in \u001b[0;36mlogs_for_transform_job\u001b[0;34m(self, job_name, wait, poll)\u001b[0m\n\u001b[1;32m   3966\u001b[0m \u001b[0;34m\u001b[0m\u001b[0m\n\u001b[1;32m   3967\u001b[0m         \u001b[0;32mif\u001b[0m \u001b[0mwait\u001b[0m\u001b[0;34m:\u001b[0m\u001b[0;34m\u001b[0m\u001b[0;34m\u001b[0m\u001b[0m\n\u001b[0;32m-> 3968\u001b[0;31m             \u001b[0mself\u001b[0m\u001b[0;34m.\u001b[0m\u001b[0m_check_job_status\u001b[0m\u001b[0;34m(\u001b[0m\u001b[0mjob_name\u001b[0m\u001b[0;34m,\u001b[0m \u001b[0mdescription\u001b[0m\u001b[0;34m,\u001b[0m \u001b[0;34m\"TransformJobStatus\"\u001b[0m\u001b[0;34m)\u001b[0m\u001b[0;34m\u001b[0m\u001b[0;34m\u001b[0m\u001b[0m\n\u001b[0m\u001b[1;32m   3969\u001b[0m             \u001b[0;32mif\u001b[0m \u001b[0mdot\u001b[0m\u001b[0;34m:\u001b[0m\u001b[0;34m\u001b[0m\u001b[0;34m\u001b[0m\u001b[0m\n\u001b[1;32m   3970\u001b[0m                 \u001b[0mprint\u001b[0m\u001b[0;34m(\u001b[0m\u001b[0;34m)\u001b[0m\u001b[0;34m\u001b[0m\u001b[0;34m\u001b[0m\u001b[0m\n",
      "\u001b[0;32m~/anaconda3/envs/python3/lib/python3.6/site-packages/sagemaker/session.py\u001b[0m in \u001b[0;36m_check_job_status\u001b[0;34m(self, job, desc, status_key_name)\u001b[0m\n\u001b[1;32m   3337\u001b[0m                 \u001b[0mmessage\u001b[0m\u001b[0;34m=\u001b[0m\u001b[0mmessage\u001b[0m\u001b[0;34m,\u001b[0m\u001b[0;34m\u001b[0m\u001b[0;34m\u001b[0m\u001b[0m\n\u001b[1;32m   3338\u001b[0m                 \u001b[0mallowed_statuses\u001b[0m\u001b[0;34m=\u001b[0m\u001b[0;34m[\u001b[0m\u001b[0;34m\"Completed\"\u001b[0m\u001b[0;34m,\u001b[0m \u001b[0;34m\"Stopped\"\u001b[0m\u001b[0;34m]\u001b[0m\u001b[0;34m,\u001b[0m\u001b[0;34m\u001b[0m\u001b[0;34m\u001b[0m\u001b[0m\n\u001b[0;32m-> 3339\u001b[0;31m                 \u001b[0mactual_status\u001b[0m\u001b[0;34m=\u001b[0m\u001b[0mstatus\u001b[0m\u001b[0;34m,\u001b[0m\u001b[0;34m\u001b[0m\u001b[0;34m\u001b[0m\u001b[0m\n\u001b[0m\u001b[1;32m   3340\u001b[0m             )\n\u001b[1;32m   3341\u001b[0m \u001b[0;34m\u001b[0m\u001b[0m\n",
      "\u001b[0;31mUnexpectedStatusException\u001b[0m: Error for Transform job sagemaker-scikit-learn-2022-05-22-12-43-07-842: Failed. Reason: AlgorithmError: See job logs for more information"
     ]
    }
   ],
   "source": [
    "inference_transformer.transform(data = \"s3://demo-bucket-test-mlop/Churn_Demo/churn-bigml-20.csv\", \n",
    "                                content_type = \"text/csv\")"
   ]
  },
  {
   "cell_type": "code",
   "execution_count": 1,
   "id": "adb9e160",
   "metadata": {},
   "outputs": [
    {
     "name": "stdout",
     "output_type": "stream",
     "text": [
      "/home/ec2-user/SageMaker/Test_Kaustav/Kaggle_Demo\n"
     ]
    }
   ],
   "source": [
    "!pwd"
   ]
  },
  {
   "cell_type": "code",
   "execution_count": 5,
   "id": "ae964c9f",
   "metadata": {},
   "outputs": [
    {
     "name": "stdout",
     "output_type": "stream",
     "text": [
      "/home/ec2-user/SageMaker/Test_Kaustav/Kaggle_Demo\n",
      "['/home/ec2-user/SageMaker/Test_Kaustav/Kaggle_Demo/Untitled.ipynb']\n"
     ]
    }
   ],
   "source": [
    "import os\n",
    "import glob\n",
    "\n",
    "print(os.getcwd())\n",
    "# os.chdir( '/path/to/main/dir' )\n",
    "result = glob.glob( '/home/ec2-user/SageMaker/Test_Kaustav/Kaggle_Demo/*.ipynb' )\n",
    "print( result )"
   ]
  },
  {
   "cell_type": "code",
   "execution_count": null,
   "id": "3063c33b",
   "metadata": {},
   "outputs": [],
   "source": []
  }
 ],
 "metadata": {
  "kernelspec": {
   "display_name": "conda_python3",
   "language": "python",
   "name": "conda_python3"
  },
  "language_info": {
   "codemirror_mode": {
    "name": "ipython",
    "version": 3
   },
   "file_extension": ".py",
   "mimetype": "text/x-python",
   "name": "python",
   "nbconvert_exporter": "python",
   "pygments_lexer": "ipython3",
   "version": "3.6.13"
  }
 },
 "nbformat": 4,
 "nbformat_minor": 5
}
